C:\Users\Vicky\Desktop\Repository\Dark-Web>python simple_usage.py
Traceback (most recent call last):
  File "C:\Users\Vicky\anaconda3\lib\site-packages\socks.py", line 787, in connect
    super(socksocket, self).connect(proxy_addr)
ConnectionRefusedError: [WinError 10061] No connection could be made because the target machine actively refused it

During handling of the above exception, another exception occurred:

Traceback (most recent call last):
  File "C:\Users\Vicky\anaconda3\lib\site-packages\urllib3\contrib\socks.py", line 96, in _new_conn
    conn = socks.create_connection(
  File "C:\Users\Vicky\anaconda3\lib\site-packages\socks.py", line 209, in create_connection
    raise err
  File "C:\Users\Vicky\anaconda3\lib\site-packages\socks.py", line 199, in create_connection
    sock.connect((remote_host, remote_port))
  File "C:\Users\Vicky\anaconda3\lib\site-packages\socks.py", line 47, in wrapper
    return function(*args, **kwargs)
  File "C:\Users\Vicky\anaconda3\lib\site-packages\socks.py", line 800, in connect
    raise ProxyConnectionError(msg, error)
socks.ProxyConnectionError: Error connecting to SOCKS5 proxy localhost:9150: [WinError 10061] No connection could be made because the target machine actively refused it

During handling of the above exception, another exception occurred:

Traceback (most recent call last):
  File "C:\Users\Vicky\anaconda3\lib\site-packages\urllib3\connectionpool.py", line 703, in urlopen
    httplib_response = self._make_request(
  File "C:\Users\Vicky\anaconda3\lib\site-packages\urllib3\connectionpool.py", line 386, in _make_request
    self._validate_conn(conn)
  File "C:\Users\Vicky\anaconda3\lib\site-packages\urllib3\connectionpool.py", line 1042, in _validate_conn
    conn.connect()
  File "C:\Users\Vicky\anaconda3\lib\site-packages\urllib3\connection.py", line 363, in connect
    self.sock = conn = self._new_conn()
  File "C:\Users\Vicky\anaconda3\lib\site-packages\urllib3\contrib\socks.py", line 127, in _new_conn
    raise NewConnectionError(
urllib3.exceptions.NewConnectionError: <urllib3.contrib.socks.SOCKSHTTPSConnection object at 0x0000023B10E4EEE0>: Failed to establish a new connection: [WinError 10061] No connection could be made because the target machine actively refused it

During handling of the above exception, another exception occurred:

Traceback (most recent call last):
  File "C:\Users\Vicky\anaconda3\lib\site-packages\requests\adapters.py", line 489, in send
    resp = conn.urlopen(
  File "C:\Users\Vicky\anaconda3\lib\site-packages\urllib3\connectionpool.py", line 787, in urlopen
    retries = retries.increment(
  File "C:\Users\Vicky\anaconda3\lib\site-packages\urllib3\util\retry.py", line 592, in increment
    raise MaxRetryError(_pool, url, error or ResponseError(cause))
urllib3.exceptions.MaxRetryError: SOCKSHTTPSConnectionPool(host='httpbin.org', port=443): Max retries exceeded with url: /anything (Caused by NewConnectionError('<urllib3.contrib.socks.SOCKSHTTPSConnection object at 0x0000023B10E4EEE0>: Failed to establish a new connection: [WinError 10061] No connection could be made because the target machine actively refused it'))

During handling of the above exception, another exception occurred:

Traceback (most recent call last):
  File "C:\Users\Vicky\Desktop\Repository\Dark-Web\simple_usage.py", line 12, in <module>
    r = rt.get(url)
  File "C:\Users\Vicky\anaconda3\lib\site-packages\requests_tor.py", line 108, in get
    return self.request("GET", url, **kwargs)
  File "C:\Users\Vicky\anaconda3\lib\site-packages\requests_tor.py", line 101, in request
    resp = requests.request(method, url, **kwargs, proxies=proxies)
  File "C:\Users\Vicky\anaconda3\lib\site-packages\requests\api.py", line 59, in request
    return session.request(method=method, url=url, **kwargs)
  File "C:\Users\Vicky\anaconda3\lib\site-packages\requests\sessions.py", line 587, in request
    resp = self.send(prep, **send_kwargs)
  File "C:\Users\Vicky\anaconda3\lib\site-packages\requests\sessions.py", line 701, in send
    r = adapter.send(request, **kwargs)
  File "C:\Users\Vicky\anaconda3\lib\site-packages\requests\adapters.py", line 565, in send
    raise ConnectionError(e, request=request)
requests.exceptions.ConnectionError: SOCKSHTTPSConnectionPool(host='httpbin.org', port=443): Max retries exceeded with url: /anything (Caused by NewConnectionError('<urllib3.contrib.socks.SOCKSHTTPSConnection object at 0x0000023B10E4EEE0>: Failed to establish a new connection: [WinError 10061] No connection could be made because the target machine actively refused it'))

C:\Users\Vicky\Desktop\Repository\Dark-Web>    